Workbook

Sheet Data
A1: Performance measurements: OLTP (healthcare_analytics) vs star schema (healthcare_analytics_dw)
A2: Blue = measured inputs (edit these). Black = formulas. Phase 1 and Phase 2 Workbench times are from the project's own MySQL Workbench / EXPLAIN ANALYZE runs; Phase 2 server times are EXPLAIN ANALYZE on an identical copy of the 100,004-encounter dataset.
A4: Phase | B4: Dataset | C4: Timing method | D4: Query ID | E4: Query | F4: OLTP time (s) | G4: Star time (s) | H4: OLTP time (ms) | I4: Star time (ms) | J4: Speedup (x) | K4: Faster schema | L4: Time saved (s) | M4: OLTP joins | N4: Star joins | O4: OLTP rows processed | P4: Star rows processed | Q4: Row reduction | R4: Result rows | S4: Measurement note | T4: Main reason for the difference
A5: Phase 1 | B5: Small (4 encounters) | C5: EXPLAIN ANALYZE | D5: Q1 | E5: Encounters by specialty | F5: 0.000123 | G5: 0.000175 | H5: =F5*1000 -> 0.123 | I5: =G5*1000 -> 0.175 | J5: =IF(G5=0,0,F5/G5) -> 0.70285714 | K5: =IF(F5>G5,"Star","OLTP") -> OLTP | L5: =F5-G5 -> -5.2e-05 | M5: 2 | N5: 3 | O5: 4 | P5: 4 | Q5: =IF(O5=0,0,1-P5/O5) -> 0 | R5: 4 | S5: Earlier draft star query | T5: Dimension join overhead outweighs savings on tiny data
A6: Phase 1 | B6: Small (4 encounters) | C6: EXPLAIN ANALYZE | D6: Q2 | E6: Diagnosis-procedure pairs | F6: 0.000228 | G6: 0.000957 | H6: =F6*1000 -> 0.228 | I6: =G6*1000 -> 0.957 | J6: =IF(G6=0,0,F6/G6) -> 0.23824451 | K6: =IF(F6>G6,"Star","OLTP") -> OLTP | L6: =F6-G6 -> -0.000729 | M6: 4 | N6: 3 | O6: 7 | P6: 7 | Q6: =IF(O6=0,0,1-P6/O6) -> 0 | R6: 5 | S6: Earlier draft star query (bridge join at run time) | T6: Bridge join plus temporary table; no aggregate yet
A7: Phase 1 | B7: Small (4 encounters) | C7: EXPLAIN ANALYZE | D7: Q3 | E7: 30-day readmissions | F7: 0.000682 | G7: 0.000322 | H7: =F7*1000 -> 0.682 | I7: =G7*1000 -> 0.322 | J7: =IF(G7=0,0,F7/G7) -> 2.1180124 | K7: =IF(F7>G7,"Star","OLTP") -> Star | L7: =F7-G7 -> 0.00036 | M7: 3 | N7: 3 | O7: 8 | P7: 8 | Q7: =IF(O7=0,0,1-P7/O7) -> 0 | R7: 1 | S7: Earlier draft star query (self-join on fact) | T7: Fact table searched by patient and datetime
A8: Phase 1 | B8: Small (4 encounters) | C8: EXPLAIN ANALYZE | D8: Q4 | E8: Revenue by specialty | F8: 0.000247 | G8: 0.000275 | H8: =F8*1000 -> 0.247 | I8: =G8*1000 -> 0.275 | J8: =IF(G8=0,0,F8/G8) -> 0.89818182 | K8: =IF(F8>G8,"Star","OLTP") -> OLTP | L8: =F8-G8 -> -2.8e-05 | M8: 3 | N8: 3 | O8: 2 | P8: 2 | Q8: =IF(O8=0,0,1-P8/O8) -> 0 | R8: 2 | S8: Earlier draft star query (separate fact_billing) | T8: Extra fact-to-fact join on tiny data
A9: Phase 2 | B9: Large (100,004 encounters) | C9: Workbench median | D9: Q1 | E9: Encounters by specialty | F9: 0.4 | G9: 0.094 | H9: =F9*1000 -> 400 | I9: =G9*1000 -> 94 | J9: =IF(G9=0,0,F9/G9) -> 4.2553191 | K9: =IF(F9>G9,"Star","OLTP") -> Star | L9: =F9-G9 -> 0.306 | M9: 2 | N9: 3 | O9: 100004 | P9: 100004 | Q9: =IF(O9=0,0,1-P9/O9) -> 0 | R9: 171 | S9: Median of Workbench runs | T9: Specialty key on fact row; covering index; integer month key
A10: Phase 2 | B10: Large (100,004 encounters) | C10: Workbench median | D10: Q2 | E10: Diagnosis-procedure pairs | F10: 2.75 | G10: 0.016 | H10: =F10*1000 -> 2750 | I10: =G10*1000 -> 16 | J10: =IF(G10=0,0,F10/G10) -> 171.875 | K10: =IF(F10>G10,"Star","OLTP") -> Star | L10: =F10-G10 -> 2.734 | M10: 4 | N10: 2 | O10: 266673 | P10: 449 | Q10: =IF(O10=0,0,1-P10/O10) -> 0.99831629 | R10: 9 | S10: Star showed 0.000 s; 0.016 s is Workbench's resolution, so this speedup is a lower bound | T10: Pair counts pre-computed in ETL aggregate
A11: Phase 2 | B11: Large (100,004 encounters) | C11: Workbench median | D11: Q3 | E11: 30-day readmissions | F11: 0.73 | G11: 0.016 | H11: =F11*1000 -> 730 | I11: =G11*1000 -> 16 | J11: =IF(G11=0,0,F11/G11) -> 45.625 | K11: =IF(F11>G11,"Star","OLTP") -> Star | L11: =F11-G11 -> 0.714 | M11: 3 | N11: 1 | O11: 350014 | P11: 25001 | Q11: =IF(O11=0,0,1-P11/O11) -> 0.92857143 | R11: 1 | S11: Star at Workbench's ~16 ms resolution; see server-time row | T11: Readmission flag pre-computed; filtered covering index
A12: Phase 2 | B12: Large (100,004 encounters) | C12: Workbench median | D12: Q4 | E12: Revenue by specialty | F12: 0.89 | G12: 0.125 | H12: =F12*1000 -> 890 | I12: =G12*1000 -> 125 | J12: =IF(G12=0,0,F12/G12) -> 7.12 | K12: =IF(F12>G12,"Star","OLTP") -> Star | L12: =F12-G12 -> 0.765 | M12: 3 | N12: 2 | O12: 200006 | P12: 100004 | Q12: =IF(O12=0,0,1-P12/O12) -> 0.499995 | R12: 168 | S12: Median of Workbench runs | T12: Billing totals on fact row; covering index; no billing join
A13: Phase 2 | B13: Large (100,004 encounters) | C13: Server time (EXPLAIN ANALYZE) | D13: Q1 | E13: Encounters by specialty | F13: 0.262 | G13: 0.067 | H13: =F13*1000 -> 262 | I13: =G13*1000 -> 67 | J13: =IF(G13=0,0,F13/G13) -> 3.9104478 | K13: =IF(F13>G13,"Star","OLTP") -> Star | L13: =F13-G13 -> 0.195 | M13: 2 | N13: 3 | O13: 100004 | P13: 100004 | Q13: =IF(O13=0,0,1-P13/O13) -> 0 | R13: 171 | S13: Server time, identical copy of the data | T13: Specialty key on fact row; covering index; integer month key
A14: Phase 2 | B14: Large (100,004 encounters) | C14: Server time (EXPLAIN ANALYZE) | D14: Q2 | E14: Diagnosis-procedure pairs | F14: 1.208 | G14: 0.00027 | H14: =F14*1000 -> 1208 | I14: =G14*1000 -> 0.27 | J14: =IF(G14=0,0,F14/G14) -> 4474.0741 | K14: =IF(F14>G14,"Star","OLTP") -> Star | L14: =F14-G14 -> 1.20773 | M14: 4 | N14: 2 | O14: 266673 | P14: 449 | Q14: =IF(O14=0,0,1-P14/O14) -> 0.99831629 | R14: 9 | S14: Server time, identical copy of the data | T14: Pair counts pre-computed in ETL aggregate
A15: Phase 2 | B15: Large (100,004 encounters) | C15: Server time (EXPLAIN ANALYZE) | D15: Q3 | E15: 30-day readmissions | F15: 0.501 | G15: 0.018 | H15: =F15*1000 -> 501 | I15: =G15*1000 -> 18 | J15: =IF(G15=0,0,F15/G15) -> 27.833333 | K15: =IF(F15>G15,"Star","OLTP") -> Star | L15: =F15-G15 -> 0.483 | M15: 3 | N15: 1 | O15: 350014 | P15: 25001 | Q15: =IF(O15=0,0,1-P15/O15) -> 0.92857143 | R15: 1 | S15: Server time, identical copy of the data | T15: Readmission flag pre-computed; filtered covering index
A16: Phase 2 | B16: Large (100,004 encounters) | C16: Server time (EXPLAIN ANALYZE) | D16: Q4 | E16: Revenue by specialty | F16: 0.483 | G16: 0.072 | H16: =F16*1000 -> 483 | I16: =G16*1000 -> 72 | J16: =IF(G16=0,0,F16/G16) -> 6.7083333 | K16: =IF(F16>G16,"Star","OLTP") -> Star | L16: =F16-G16 -> 0.411 | M16: 3 | N16: 2 | O16: 200006 | P16: 100004 | Q16: =IF(O16=0,0,1-P16/O16) -> 0.499995 | R16: 168 | S16: Server time, identical copy of the data | T16: Billing totals on fact row; covering index; no billing join

Sheet Summary
A1: Summary tables (all cells are formulas linked to the Data sheet; charts read from here)
A3: 1. Large dataset (100,004 encounters): Workbench median, seconds
A4: Query | B4: OLTP (s) | C4: Star (s) | D4: Speedup (x) | E4: Query name
A5: =Data!D9 -> Q1 | B5: =Data!F9 -> 0.4 | C5: =Data!G9 -> 0.094 | D5: =IF(C5=0,0,B5/C5) -> 4.2553191 | E5: =Data!E9 -> Encounters by specialty
A6: =Data!D10 -> Q2 | B6: =Data!F10 -> 2.75 | C6: =Data!G10 -> 0.016 | D6: =IF(C6=0,0,B6/C6) -> 171.875 | E6: =Data!E10 -> Diagnosis-procedure pairs
A7: =Data!D11 -> Q3 | B7: =Data!F11 -> 0.73 | C7: =Data!G11 -> 0.016 | D7: =IF(C7=0,0,B7/C7) -> 45.625 | E7: =Data!E11 -> 30-day readmissions
A8: =Data!D12 -> Q4 | B8: =Data!F12 -> 0.89 | C8: =Data!G12 -> 0.125 | D8: =IF(C8=0,0,B8/C8) -> 7.12 | E8: =Data!E12 -> Revenue by specialty
A10: 2. Large dataset: server time (EXPLAIN ANALYZE), seconds
A11: Query | B11: OLTP (s) | C11: Star (s) | D11: Speedup (x) | E11: Query name
A12: =Data!D13 -> Q1 | B12: =Data!F13 -> 0.262 | C12: =Data!G13 -> 0.067 | D12: =IF(C12=0,0,B12/C12) -> 3.9104478 | E12: =Data!E13 -> Encounters by specialty
A13: =Data!D14 -> Q2 | B13: =Data!F14 -> 1.208 | C13: =Data!G14 -> 0.00027 | D13: =IF(C13=0,0,B13/C13) -> 4474.0741 | E13: =Data!E14 -> Diagnosis-procedure pairs
A14: =Data!D15 -> Q3 | B14: =Data!F15 -> 0.501 | C14: =Data!G15 -> 0.018 | D14: =IF(C14=0,0,B14/C14) -> 27.833333 | E14: =Data!E15 -> 30-day readmissions
A15: =Data!D16 -> Q4 | B15: =Data!F16 -> 0.483 | C15: =Data!G16 -> 0.072 | D15: =IF(C15=0,0,B15/C15) -> 6.7083333 | E15: =Data!E16 -> Revenue by specialty
A17: 3. Small dataset (4 encounters), milliseconds
A18: Query | B18: OLTP (ms) | C18: Star (ms) | D18: Speedup (x) | E18: Query name
A19: =Data!D5 -> Q1 | B19: =Data!H5 -> 0.123 | C19: =Data!I5 -> 0.175 | D19: =IF(C19=0,0,B19/C19) -> 0.70285714 | E19: =Data!E5 -> Encounters by specialty
A20: =Data!D6 -> Q2 | B20: =Data!H6 -> 0.228 | C20: =Data!I6 -> 0.957 | D20: =IF(C20=0,0,B20/C20) -> 0.23824451 | E20: =Data!E6 -> Diagnosis-procedure pairs
A21: =Data!D7 -> Q3 | B21: =Data!H7 -> 0.682 | C21: =Data!I7 -> 0.322 | D21: =IF(C21=0,0,B21/C21) -> 2.1180124 | E21: =Data!E7 -> 30-day readmissions
A22: =Data!D8 -> Q4 | B22: =Data!H8 -> 0.247 | C22: =Data!I8 -> 0.275 | D22: =IF(C22=0,0,B22/C22) -> 0.89818182 | E22: =Data!E8 -> Revenue by specialty
A24: 4. Speedup by phase (OLTP time / star time; below 1x = star slower)
A25: Query | B25: Small dataset | C25: Large, Workbench | D25: Large, server time | E25: Query name
A26: =Data!D5 -> Q1 | B26: =D19 -> 0.70285714 | C26: =D5 -> 4.2553191 | D26: =D12 -> 3.9104478 | E26: =Data!E5 -> Encounters by specialty
A27: =Data!D6 -> Q2 | B27: =D20 -> 0.23824451 | C27: =D6 -> 171.875 | D27: =D13 -> 4474.0741 | E27: =Data!E6 -> Diagnosis-procedure pairs
A28: =Data!D7 -> Q3 | B28: =D21 -> 2.1180124 | C28: =D7 -> 45.625 | D28: =D14 -> 27.833333 | E28: =Data!E7 -> 30-day readmissions
A29: =Data!D8 -> Q4 | B29: =D22 -> 0.89818182 | C29: =D8 -> 7.12 | D29: =D15 -> 6.7083333 | E29: =Data!E8 -> Revenue by specialty
A31: 5. Large dataset: rows processed
A32: Query | B32: OLTP rows | C32: Star rows | D32: Row reduction | E32: Query name
A33: =Data!D9 -> Q1 | B33: =Data!O9 -> 100004 | C33: =Data!P9 -> 100004 | D33: =IF(B33=0,0,1-C33/B33) -> 0 | E33: =Data!E9 -> Encounters by specialty
A34: =Data!D10 -> Q2 | B34: =Data!O10 -> 266673 | C34: =Data!P10 -> 449 | D34: =IF(B34=0,0,1-C34/B34) -> 0.99831629 | E34: =Data!E10 -> Diagnosis-procedure pairs
A35: =Data!D11 -> Q3 | B35: =Data!O11 -> 350014 | C35: =Data!P11 -> 25001 | D35: =IF(B35=0,0,1-C35/B35) -> 0.92857143 | E35: =Data!E11 -> 30-day readmissions
A36: =Data!D12 -> Q4 | B36: =Data!O12 -> 200006 | C36: =Data!P12 -> 100004 | D36: =IF(B36=0,0,1-C36/B36) -> 0.499995 | E36: =Data!E12 -> Revenue by specialty
A38: 6. Growth from small to large dataset, seconds
A39: Dataset | B39: Q1 OLTP | C39: Q2 OLTP | D39: Q3 OLTP | E39: Q4 OLTP | F39: Q1 Star | G39: Q2 Star | H39: Q3 Star | I39: Q4 Star
A40: Small (4 enc.) | B40: =Data!F5 -> 0.000123 | C40: =Data!F6 -> 0.000228 | D40: =Data!F7 -> 0.000682 | E40: =Data!F8 -> 0.000247 | F40: =Data!G5 -> 0.000175 | G40: =Data!G6 -> 0.000957 | H40: =Data!G7 -> 0.000322 | I40: =Data!G8 -> 0.000275
A41: Large (100,004 enc.) | B41: =Data!F9 -> 0.4 | C41: =Data!F10 -> 2.75 | D41: =Data!F11 -> 0.73 | E41: =Data!F12 -> 0.89 | F41: =Data!G9 -> 0.094 | G41: =Data!G10 -> 0.016 | H41: =Data!G11 -> 0.016 | I41: =Data!G12 -> 0.125
A42: Growth (x) | B42: =IF(B40=0,0,B41/B40) -> 3252.0325 | C42: =IF(C40=0,0,C41/C40) -> 12061.404 | D42: =IF(D40=0,0,D41/D40) -> 1070.3812 | E42: =IF(E40=0,0,E41/E40) -> 3603.2389 | F42: =IF(F40=0,0,F41/F40) -> 537.14286 | G42: =IF(G40=0,0,G41/G40) -> 16.718913 | H42: =IF(H40=0,0,H41/H40) -> 49.689441 | I42: =IF(I40=0,0,I41/I40) -> 454.54545
A44: 7. Key figures
A45: Queries where star was faster, small dataset | B45: =COUNTIFS(Data!A5:A16,"Phase 1",Data!K5:K16,"Star")&" of 4" -> 1 of 4
A46: Queries where star was faster, large dataset (Workbench) | B46: =COUNTIFS(Data!C5:C16,"Workbench median",Data!K5:K16,"Star")&" of 4" -> 4 of 4
A47: Total OLTP time, all 4 queries, large (s) | B47: =SUM(B5:B8) -> 4.77
...

Sheet Charts
A1: Performance charts (native Excel charts; they update when the blue inputs on the Data sheet change)
A66: Note: Q2 and Q3 star Workbench times (chart 1) are at Workbench's ~16 ms timer resolution; chart 2 shows the precise server times.
